Workbook

Sheet Final (2)
A1: Unique ID | B1: title | C1: artist | D1: year | E1: decade | F1: original_vocal | G1: categories | H1: social_singing
A2: =CONCATENATE(B2,C2) -> 23Chayce Beckham | B2: 23 | C2: Chayce Beckham | D2: 2021 | E2: 2020s | F2: Male | G2: Country
A3: =CONCATENATE(B3,C3) -> 23Sam Hunt | B3: 23 | C3: Sam Hunt | D3: 2021 | E3: 2020s | F3: Male | G3: Country
A4: =CONCATENATE(B4,C4) -> 45Shinedown | B4: 45 | C4: Shinedown | D4: 2003 | E4: 2000s | F4: Male | G4: Rock
A5: =CONCATENATE(B5,C5) -> 1985Bowling for Soup | B5: 1985 | C5: Bowling for Soup | D5: 2004 | E5: 2000s | F5: Male | G5: Emo / Pop Punk | H5: Group Songs
A6: =CONCATENATE(B6,C6) -> 3005Childish Gambino | B6: 3005 | C6: Childish Gambino | D6: 2013 | E6: 2010s | F6: Male | G6: Hip-Hop
A7: =CONCATENATE(B7,C7) -> #SELFIEThe Chainsmokers | B7: #SELFIE | C7: The Chainsmokers | D7: 2014 | E7: 2010s | F7: Female | G7: EDM / Pop
A8: =CONCATENATE(B8,C8) -> (I Can't Get No) SatisfactionThe Rolling Stones | B8: (I Can't Get No) Satisfaction | C8: The Rolling Stones | D8: 1965 | E8: 1960s | F8: Male | G8: Rock | H8: Group Songs
A9: =CONCATENATE(B9,C9) -> (Kissed You) Good NightGloriana | B9: (Kissed You) Good Night | C9: Gloriana | D9: 2012 | E9: 2010s | F9: Mixed | G9: Country
A10: =CONCATENATE(B10,C10) -> (You Make Me Feel Like) A Natural WomanCarole King | B10: (You Make Me Feel Like) A Natural Woman | C10: Carole King | D10: 1971 | E10: 1970s | F10: Female | G10: Soul / Pop
A11: =CONCATENATE(B11,C11) -> 'Til Summer Comes AroundKeith Urban | B11: 'Til Summer Comes Around | C11: Keith Urban | D11: 2009 | E11: 2000s | F11: Male | G11: Country
A12: =CONCATENATE(B12,C12) -> 'Til You Can'tCody Johnson | B12: 'Til You Can't | C12: Cody Johnson | D12: 2021 | E12: 2020s | F12: Male | G12: Country
A13: =CONCATENATE(B13,C13) -> 0 to 100 / The Catch Up (Explicit)Drake | B13: 0 to 100 / The Catch Up (Explicit) | C13: Drake | D13: 2014 | E13: 2010s | F13: Male | G13: Hip-Hop, Rap
A14: =CONCATENATE(B14,C14) -> 1, 2 ManyLuke Combs ft. Brooks & Dunn | B14: 1, 2 Many | C14: Luke Combs ft. Brooks & Dunn | D14: 2019 | E14: 2010s | F14: Male | G14: Country
A15: =CONCATENATE(B15,C15) -> 1, 2, 3, 4Plain White T's | B15: 1, 2, 3, 4 | C15: Plain White T's | D15: 2008 | E15: 2000s | F15: Male | G15: Pop
A16: =CONCATENATE(B16,C16) -> 10 Million PeopleExample | B16: 10 Million People | C16: Example | D16: 2014 | E16: 2010s | F16: Male | G16: Pop
A17: =CONCATENATE(B17,C17) -> 10 Things I Hate About YouLeah Kate | B17: 10 Things I Hate About You | C17: Leah Kate | D17: 2022 | E17: 2020s | F17: Female | G17: Pop
A18: =CONCATENATE(B18,C18) -> 10,000 HoursDan + Shay & Justin Bieber | B18: 10,000 Hours | C18: Dan + Shay & Justin Bieber | D18: 2019 | E18: 2010s | F18: Male | G18: Pop/Country
A19: =CONCATENATE(B19,C19) -> 18 and LifeSkid Row | B19: 18 and Life | C19: Skid Row | D19: 1989 | E19: 1980s | F19: Male | G19: Metal / Hard Rock
A20: =CONCATENATE(B20,C20) -> 1-800-273-8255Logic ft. Alessia Cara & Khalid | B20: 1-800-273-8255 | C20: Logic ft. Alessia Cara & Khalid | D20: 2017 | E20: 2010s | F20: Mixed | G20: Hip-Hop
... A34: =CONCATENATE(B34,C34) -> 8 Second RideJake Owen | B34: 8 Second Ride | C34: Jake Owen | D34: 2006 | E34: 2000s | F34: Male | G34: Country
A35: =CONCATENATE(B35,C35) -> 90's CountryWalker Hayes | B35: 90's Country | C35: Walker Hayes | D35: 2022 | E35: 2020s | F35: Male | G35: Country | H35: Group Songs
A36: =CONCATENATE(B36,C36) -> 99 LuftballonsNena | B36: 99 Luftballons | C36: Nena | D36: 1983 | E36: 1980s | F36: Female | G36: Pop | H36: Group Songs
A37: =CONCATENATE(B37,C37) -> A Bar Song (Tipsy)Shaboozey | B37: A Bar Song (Tipsy) | C37: Shaboozey | D37: 2024 | E37: 2020s | F37: Male | G37: Country/Hip-Hop
A38: =CONCATENATE(B38,C38) -> A Billion GirlsElyar Fox | B38: A Billion Girls | C38: Elyar Fox | D38: 2014 | E38: 2010s | F38: Male | G38: Pop
A39: =CONCATENATE(B39,C39) -> A Different WorldBucky Covington | B39: A Different World | C39: Bucky Covington | D39: 2007 | E39: 2000s | F39: Male | G39: Country
A40: =CONCATENATE(B40,C40) -> A Good Hearted WomanLeAnn Rimes | B40: A Good Hearted Woman | C40: LeAnn Rimes | D40: 1999 | E40: 1990s | F40: Female | G40: Country
A41: =CONCATENATE(B41,C41) -> A Guy Walks into a BarTyler Farr | B41: A Guy Walks into a Bar | C41: Tyler Farr | D41: 2015 | E41: 2010s | F41: Male | G41: Country
A42: =CONCATENATE(B42,C42) -> A Little Bit OffFive Finger Death Punch | B42: A Little Bit Off | C42: Five Finger Death Punch | D42: 2020 | E42: 2020s | F42: Male | G42: Rock
A43: =CONCATENATE(B43,C43) -> A Little Dive Bar in DahlonegaAshley McBryde | B43: A Little Dive Bar in Dahlonega | C43: Ashley McBryde | D43: 2017 | E43: 2010s | F43: Female | G43: Country
A44: =CONCATENATE(B44,C44) -> A Little More SummertimeJason Aldean | B44: A Little More Summertime | C44: Jason Aldean | D44: 2016 | E44: 2010s | F44: Male | G44: Country
A45: =CONCATENATE(B45,C45) -> A Little More YouLittle Big Town | B45: A Little More You | C45: Little Big Town | D45: 2007 | E45: 2000s | F45: Mixed | G45: Country
A46: =CONCATENATE(B46,C46) -> A Love That Will LastRenee Olstead | B46: A Love That Will Last | C46: Renee Olstead | D46: 2004 | E46: 2000s | F46: Female | G46: Jazz / Pop
A47: =CONCATENATE(B47,C47) -> A Million DreamsThe Greatest Showman Cast | B47: A Million Dreams | C47: The Greatest Showman Cast | D47: 2017 | E47: 2010s | F47: Mixed | G47: Musical
A48: =CONCATENATE(B48,C48) -> A Quick Death in TexasClutch | B48: A Quick Death in Texas | C48: Clutch | D48: 2022 | E48: 2020s | F48: Male | G48: Rock
A49: =CONCATENATE(B49,C49) -> A Sky Full of StarsColdplay | B49: A Sky Full of Stars | C49: Coldplay | D49: 2014 | E49: 2010s | F49: Male | G49: Pop, Rock | H49: Group Songs
A50: =CONCATENATE(B50,C50) -> A Symptom of Being HumanShinedown | B50: A Symptom of Being Human | C50: Shinedown | D50: 2022 | E50: 2020s | F50: Male | G50: Rock
A51: =CONCATENATE(B51,C51) -> A Woman Like YouLee Brice | B51: A Woman Like You | C51: Lee Brice | D51: 2012 | E51: 2010s | F51: Male | G51: Country
A52: =CONCATENATE(B52,C52) -> AAWalker Hayes | B52: AA | C52: Walker Hayes | D52: 2022 | E52: 2020s | F52: Male | G52: Country
A53: =CONCATENATE(B53,C53) -> abcdefuGAYLE | B53: abcdefu | C53: GAYLE | D53: 2021 | E53: 2020s | F53: Female | G53: Pop | H53: Group Songs
...

Sheet Totals
A1: Song listings at start | B1: 2681
A2: Final number of songs
A3: Hours worked

Sheet Final
A1: Unique ID | B1: title | C1: artist | D1: year | E1: decade | F1: original_vocal | G1: categories | H1: social_singing
A2: =CONCATENATE(B2,C2) -> 23Chayce Beckham | B2: 23 | C2: Chayce Beckham | D2: 2021 | E2: 2020s | F2: Male | G2: =VLOOKUP(A:A,Export!A:F,6,FALSE) -> Country
A3: =CONCATENATE(B3,C3) -> 23Sam Hunt | B3: 23 | C3: Sam Hunt | D3: 2021 | E3: 2020s | F3: Male | G3: =VLOOKUP(A:A,Export!A:F,6,FALSE) -> Country
A4: =CONCATENATE(B4,C4) -> 45Shinedown | B4: 45 | C4: Shinedown | D4: 2003 | E4: 2000s | F4: Male | G4: =VLOOKUP(A:A,Export!A:F,6,FALSE) -> Rock
A5: =CONCATENATE(B5,C5) -> 1985Bowling for Soup | B5: 1985 | C5: Bowling for Soup | D5: 2004 | E5: 2000s | F5: Male | G5: =VLOOKUP(A:A,Export!A:F,6,FALSE) -> Emo / Pop Punk | H5: =VLOOKUP(A:A,Export!A:G,7,FALSE) -> Group Songs
A6: =CONCATENATE(B6,C6) -> 3005Childish Gambino | B6: 3005 | C6: Childish Gambino | D6: 2013 | E6: 2010s | F6: Male | G6: =VLOOKUP(A:A,Export!A:F,6,FALSE) -> Hip-Hop
A7: =CONCATENATE(B7,C7) -> #SELFIEThe Chainsmokers | B7: #SELFIE | C7: The Chainsmokers | D7: 2014 | E7: 2010s | F7: Female | G7: =VLOOKUP(A:A,Export!A:F,6,FALSE) -> EDM / Pop
A8: =CONCATENATE(B8,C8) -> (I Can’t Get No) SatisfactionThe Rolling Stones | B8: (I Can’t Get No) Satisfaction | C8: The Rolling Stones | D8: 1965 | E8: 1960s | F8: Male | G8: =VLOOKUP(A:A,Export!A:F,6,FALSE) -> Rock | H8: =VLOOKUP(A:A,Export!A:G,7,FALSE) -> Group Songs
A9: =CONCATENATE(B9,C9) -> (Kissed You) Good NightGloriana | B9: (Kissed You) Good Night | C9: Gloriana | D9: 2012 | E9: 2010s | F9: Mixed | G9: =VLOOKUP(A:A,Export!A:F,6,FALSE) -> Country
A10: =CONCATENATE(B10,C10) -> (You Make Me Feel Like) A Natural WomanCarole King | B10: (You Make Me Feel Like) A Natural Woman | C10: Carole King | D10: 1971 | E10: 1970s | F10: Female | G10: =VLOOKUP(A:A,Export!A:F,6,FALSE) -> Soul / Pop
A11: =CONCATENATE(B11,C11) -> ’Til Summer Comes AroundKeith Urban | B11: ’Til Summer Comes Around | C11: Keith Urban | D11: 2009 | E11: 2000s | F11: Male | G11: =VLOOKUP(A:A,Export!A:F,6,FALSE) -> Country
A12: =CONCATENATE(B12,C12) -> ’Til You Can’tCody Johnson | B12: ’Til You Can’t | C12: Cody Johnson | D12: 2021 | E12: 2020s | F12: Male | G12: =VLOOKUP(A:A,Export!A:F,6,FALSE) -> Country
A13: =CONCATENATE(B13,C13) -> 0 to 100 / The Catch Up (Explicit)Drake | B13: 0 to 100 / The Catch Up (Explicit) | C13: Drake | D13: 2014 | E13: 2010s | F13: Male | G13: =VLOOKUP(A:A,Export!A:F,6,FALSE) -> Hip-Hop, Rap
A14: =CONCATENATE(B14,C14) -> 1, 2 ManyLuke Combs ft. Brooks & Dunn | B14: 1, 2 Many | C14: Luke Combs ft. Brooks & Dunn | D14: 2019 | E14: 2010s | F14: Male | G14: =VLOOKUP(A:A,Export!A:F,6,FALSE) -> Country
A15: =CONCATENATE(B15,C15) -> 1, 2, 3, 4Plain White T’s | B15: 1, 2, 3, 4 | C15: Plain White T’s | D15: 2008 | E15: 2000s | F15: Male | G15: =VLOOKUP(A:A,Export!A:F,6,FALSE) -> Pop
A16: =CONCATENATE(B16,C16) -> 10 Million PeopleExample | B16: 10 Million People | C16: Example | D16: 2014 | E16: 2010s | F16: Male | G16: =VLOOKUP(A:A,Export!A:F,6,FALSE) -> Pop
A17: =CONCATENATE(B17,C17) -> 10 Things I Hate About YouLeah Kate | B17: 10 Things I Hate About You | C17: Leah Kate | D17: 2022 | E17: 2020s | F17: Female | G17: =VLOOKUP(A:A,Export!A:F,6,FALSE) -> Pop
A18: =CONCATENATE(B18,C18) -> 10,000 HoursDan + Shay & Justin Bieber | B18: 10,000 Hours | C18: Dan + Shay & Justin Bieber | D18: 2019 | E18: 2010s | F18: Male | G18: =VLOOKUP(A:A,Export!A:F,6,FALSE) -> Pop/Country
A19: =CONCATENATE(B19,C19) -> 18 and LifeSkid Row | B19: 18 and Life | C19: Skid Row | D19: 1989 | E19: 1980s | F19: Male | G19: =VLOOKUP(A:A,Export!A:F,6,FALSE) -> Metal / Hard Rock
A20: =CONCATENATE(B20,C20) -> 1-800-273-8255Logic ft. Alessia Cara & Khalid | B20: 1-800-273-8255 | C20: Logic ft. Alessia Cara & Khalid | D20: 2017 | E20: 2010s | F20: Mixed | G20: =VLOOKUP(A:A,Export!A:F,6,FALSE) -> Hip-Hop
... A34: =CONCATENATE(B34,C34) -> 8 Second RideJake Owen | B34: 8 Second Ride | C34: Jake Owen | D34: 2006 | E34: 2000s | F34: Male | G34: =VLOOKUP(A:A,Export!A:F,6,FALSE) -> Country
A35: =CONCATENATE(B35,C35) -> 90’s CountryWalker Hayes | B35: 90’s Country | C35: Walker Hayes | D35: 2022 | E35: 2020s | F35: Male | G35: =VLOOKUP(A:A,Export!A:F,6,FALSE) -> Country | H35: =VLOOKUP(A:A,Export!A:G,7,FALSE) -> Group Songs
A36: =CONCATENATE(B36,C36) -> 99 LuftballonsNena | B36: 99 Luftballons | C36: Nena | D36: 1983 | E36: 1980s | F36: Female | G36: =VLOOKUP(A:A,Export!A:F,6,FALSE) -> Pop | H36: =VLOOKUP(A:A,Export!A:G,7,FALSE) -> Group Songs
A37: =CONCATENATE(B37,C37) -> A Bar Song (Tipsy)Shaboozey | B37: A Bar Song (Tipsy) | C37: Shaboozey | D37: 2024 | E37: 2020s | F37: Male | G37: =VLOOKUP(A:A,Export!A:F,6,FALSE) -> Country/Hip-Hop
A38: =CONCATENATE(B38,C38) -> A Billion GirlsElyar Fox | B38: A Billion Girls | C38: Elyar Fox | D38: 2014 | E38: 2010s | F38: Male | G38: =VLOOKUP(A:A,Export!A:F,6,FALSE) -> Pop
A39: =CONCATENATE(B39,C39) -> A Different WorldBucky Covington | B39: A Different World | C39: Bucky Covington | D39: 2007 | E39: 2000s | F39: Male | G39: =VLOOKUP(A:A,Export!A:F,6,FALSE) -> Country
A40: =CONCATENATE(B40,C40) -> A Good Hearted WomanLeAnn Rimes | B40: A Good Hearted Woman | C40: LeAnn Rimes | D40: 1999 | E40: 1990s | F40: Female | G40: =VLOOKUP(A:A,Export!A:F,6,FALSE) -> Country
A41: =CONCATENATE(B41,C41) -> A Guy Walks into a BarTyler Farr | B41: A Guy Walks into a Bar | C41: Tyler Farr | D41: 2015 | E41: 2010s | F41: Male | G41: =VLOOKUP(A:A,Export!A:F,6,FALSE) -> Country
A42: =CONCATENATE(B42,C42) -> A Little Bit OffFive Finger Death Punch | B42: A Little Bit Off | C42: Five Finger Death Punch | D42: 2020 | E42: 2020s | F42: Male | G42: =VLOOKUP(A:A,Export!A:F,6,FALSE) -> Rock
A43: =CONCATENATE(B43,C43) -> A Little Dive Bar in DahlonegaAshley McBryde | B43: A Little Dive Bar in Dahlonega | C43: Ashley McBryde | D43: 2017 | E43: 2010s | F43: Female | G43: =VLOOKUP(A:A,Export!A:F,6,FALSE) -> Country
A44: =CONCATENATE(B44,C44) -> A Little More SummertimeJason Aldean | B44: A Little More Summertime | C44: Jason Aldean | D44: 2016 | E44: 2010s | F44: Male | G44: =VLOOKUP(A:A,Export!A:F,6,FALSE) -> Country
A45: =CONCATENATE(B45,C45) -> A Little More YouLittle Big Town | B45: A Little More You | C45: Little Big Town | D45: 2007 | E45: 2000s | F45: Mixed | G45: =VLOOKUP(A:A,Export!A:F,6,FALSE) -> Country
A46: =CONCATENATE(B46,C46) -> A Love That Will LastRenee Olstead | B46: A Love That Will Last | C46: Renee Olstead | D46: 2004 | E46: 2000s | F46: Female | G46: =VLOOKUP(A:A,Export!A:F,6,FALSE) -> Jazz / Pop
A47: =CONCATENATE(B47,C47) -> A Million DreamsThe Greatest Showman Cast | B47: A Million Dreams | C47: The Greatest Showman Cast | D47: 2017 | E47: 2010s | F47: Mixed | G47: =VLOOKUP(A:A,Export!A:F,6,FALSE) -> Musical
A48: =CONCATENATE(B48,C48) -> A Quick Death in TexasClutch | B48: A Quick Death in Texas | C48: Clutch | D48: 2022 | E48: 2020s | F48: Male | G48: =VLOOKUP(A:A,Export!A:F,6,FALSE) -> Rock
A49: =CONCATENATE(B49,C49) -> A Sky Full of StarsColdplay | B49: A Sky Full of Stars | C49: Coldplay | D49: 2014 | E49: 2010s | F49: Male | G49: =VLOOKUP(A:A,Export!A:F,6,FALSE) -> Pop, Rock | H49: =VLOOKUP(A:A,Export!A:G,7,FALSE) -> Group Songs
A50: =CONCATENATE(B50,C50) -> A Symptom of Being HumanShinedown | B50: A Symptom of Being Human | C50: Shinedown | D50: 2022 | E50: 2020s | F50: Male | G50: =VLOOKUP(A:A,Export!A:F,6,FALSE) -> Rock
A51: =CONCATENATE(B51,C51) -> A Woman Like YouLee Brice | B51: A Woman Like You | C51: Lee Brice | D51: 2012 | E51: 2010s | F51: Male | G51: =VLOOKUP(A:A,Export!A:F,6,FALSE) -> Country
A52: =CONCATENATE(B52,C52) -> AAWalker Hayes | B52: AA | C52: Walker Hayes | D52: 2022 | E52: 2020s | F52: Male | G52: =VLOOKUP(A:A,Export!A:F,6,FALSE) -> Country
A53: =CONCATENATE(B53,C53) -> abcdefuGAYLE | B53: abcdefu | C53: GAYLE | D53: 2021 | E53: 2020s | F53: Female | G53: =VLOOKUP(A:A,Export!A:F,6,FALSE) -> Pop | H53: =VLOOKUP(A:A,Export!A:G,7,FALSE) -> Group Songs
...

Sheet Export
A1: Unique ID | B1: title | C1: artist | D1: year | E1: decade | F1: categories | G1: social_singing | H1: original_vocal | I1: possible_duplicate | J1: match_confidence | K1: needs_review | L1: notes | M1: raw_input
A2: =CONCATENATE(B2,C2) -> Word Crimes"Weird Al" Yankovic | B2: Word Crimes | C2: "Weird Al" Yankovic | D2: 2014 | E2: 2010s | F2: Novelty / Comedy, Pop | G2: Group Songs | H2: Male | J2: High | L2: corrected artist spelling | M2: G28959 - Word Crimes - Weird Al Yankovich.cdg
A3: =CONCATENATE(B3,C3) -> 10 Million PeopleExample | B3: 10 Million People | C3: Example | D3: 2014 | E3: 2010s | F3: Pop | H3: Male | J3: High | L3: removed catalog code and file extension | M3: SF344-11 - Example - 10 Million People.cdg
A4: =CONCATENATE(B4,C4) -> A Sky Full of StarsColdplay | B4: A Sky Full of Stars | C4: Coldplay | D4: 2014 | E4: 2010s | F4: Pop, Rock | G4: Group Songs | H4: Male | J4: High | L4: corrected title to standard release form
A5: =CONCATENATE(B5,C5) -> She Looks So Perfect5 Seconds of Summer | B5: She Looks So Perfect | C5: 5 Seconds of Summer | D5: 2014 | E5: 2010s | F5: Pop, Rock | G5: Group Songs | H5: Male | J5: High | L5: normalized artist styling | M5: KCDPR1408-02 - 5 Seconds Of Summer - She Looks So Perfect.cdg
A6: =CONCATENATE(B6,C6) -> Play BallAC/DC | B6: Play Ball | C6: AC/DC | D6: 2014 | E6: 2010s | F6: Rock | H6: Male | I6: Possible Duplicate | J6: High | L6: variant version present | M6: DFK091-05 - AC-DC - Play Ball (Wbgv).zip
A7: =CONCATENATE(B7,C7) -> Play Ball (with vocal)AC/DC | B7: Play Ball (with vocal) | C7: AC/DC | D7: 2014 | E7: 2010s | F7: Rock | H7: Male | J7: High | M7: DFK091-04 - AC-DC - Play Ball (Wvocal).zip
A8: =CONCATENATE(B8,C8) -> It's On AgainAlicia Keys feat. Kendrick Lamar | B8: It's On Again | C8: Alicia Keys feat. Kendrick Lamar | D8: 2014 | E8: 2010s | F8: R&B, Pop | H8: Female | J8: High | L8: normalized featured artist formatting | M8: MRH117-16 - Alicia Keys Ft Kendrick Lamar - It's On Again.cdg
A9: =CONCATENATE(B9,C9) -> BelieverAmerican Authors | B9: Believer | C9: American Authors | D9: 2014 | E9: 2010s | F9: Alternative / Indie, Rock | G9: Group Songs | H9: Male | J9: High | L9: removed catalog code and file extension | M9: KCDPR1408-04 - American Authors - Believer.cdg
A10: =CONCATENATE(B10,C10) -> Snap Out of ItArctic Monkeys | B10: Snap Out of It | C10: Arctic Monkeys | D10: 2013 | E10: 2010s | F10: Rock, Alternative / Indie | H10: Male | J10: High | L10: normalized title capitalization | M10: SF341-03 - Arctic Monkeys - Snap Out Of It.cdg
A11: =CONCATENATE(B11,C11) -> All About That BassMeghan Trainor | B11: All About That Bass | C11: Meghan Trainor | D11: 2014 | E11: 2010s | F11: Pop | G11: Group Songs | H11: Female | J11: High
A12: =CONCATENATE(B12,C12) -> Break FreeAriana Grande feat. Zedd | B12: Break Free | C12: Ariana Grande feat. Zedd | D12: 2014 | E12: 2010s | F12: Pop, Dance / Disco | G12: Group Songs | H12: Female | J12: High | L12: normalized featured artist formatting | M12: MRH119-17 - Ariana Grande Ft Zedd - Break Free.cdg
A13: =CONCATENATE(B13,C13) -> Lay Me DownAvicii feat. Adam Lambert | B13: Lay Me Down | C13: Avicii feat. Adam Lambert | D13: 2014 | E13: 2010s | F13: Dance / Disco, Pop | G13: Group Songs | H13: Male | J13: High | L13: normalized featured artist formatting | M13: MRH119-11 - Avicii Ft Adam Lambert - Lay Me Down.cdg
A14: =CONCATENATE(B14,C14) -> Am I WrongNico & Vinz | B14: Am I Wrong | C14: Nico & Vinz | D14: 2013 | E14: 2010s | F14: Pop | G14: Group Songs | H14: Male | J14: High | L14: removed catalog code and file extension
A15: =CONCATENATE(B15,C15) -> ShowerBecky G | B15: Shower | C15: Becky G | D15: 2014 | E15: 2010s | F15: Pop | G15: Group Songs | H15: Female | J15: High | L15: removed catalog code and file extension | M15: G28922 - Shower - Becky G.cdg
A16: =CONCATENATE(B16,C16) -> Mine (Explicit)Beyoncé feat. Drake | B16: Mine (Explicit) | C16: Beyoncé feat. Drake | D16: 2013 | E16: 2010s | F16: R&B, Pop | H16: Female | J16: High | L16: removed catalog code and file extension | M16: G28440 - Mine (explicit) - Beyonce feat. Drake.cdg
A17: =CONCATENATE(B17,C17) -> 23 Degrees and SouthBilly Currington | B17: 23 Degrees and South | C17: Billy Currington | D17: 2013 | E17: 2010s | F17: Country | H17: Male | J17: High | L17: normalized title capitalization | M17: KCD1408-02 - Billy Currington - 23 Degrees And South.cdg
A18: =CONCATENATE(B18,C18) -> Neon LightBlake Shelton | B18: Neon Light | C18: Blake Shelton | D18: 2014 | E18: 2010s | F18: Country | H18: Male | I18: Possible Duplicate | J18: High | L18: variant version present | M18: DFK091-02 - Blake Shelton - Neon Light (Wbgv).zip
A19: =CONCATENATE(B19,C19) -> Neon Light (with vocal)Blake Shelton | B19: Neon Light (with vocal) | C19: Blake Shelton | D19: 2014 | E19: 2010s | F19: Country | H19: Male | J19: High | M19: DFK091-01 - Blake Shelton - Neon Light (Wvocal).zip
A20: =CONCATENATE(B20,C20) -> MuttBlink-182 | B20: Mutt | C20: Blink-182 | D20: 1999 | E20: 90s | F20: Punk, Rock | H20: Male | J20: High | L20: cleaned filename junk | M20: Blink_182_Mutt(MP3+CDG_Karaoke)_10964551.zip
A21: =CONCATENATE(B21,C21) -> High School Never EndsBowling for Soup | B21: High School Never Ends | C21: Bowling for Soup | D21: 2006 | E21: 2000s | F21: Emo / Pop Punk | G21: Group Songs | H21: Male | J21: High | M21: Bowling_for_Soup_High_School_Never_Ends(MP3+CDG_Karaoke)_10558576.zip
A22: =CONCATENATE(B22,C22) -> One Minute MoreCapital Cities | B22: One Minute More | C22: Capital Cities | D22: 2014 | E22: 2010s | F22: Pop, Alternative / Indie | H22: Male | J22: High | L22: removed catalog code and file extension | M22: KCDPR1408-05 - Capital Cities - One Minute More.cdg
A23: =CONCATENATE(B23,C23) -> Amnesia5 Seconds of Summer | B23: Amnesia | C23: 5 Seconds of Summer | D23: 2014 | E23: 2010s | F23: Pop, Rock | G23: Group Songs | H23: Male | J23: High | L23: normalized artist styling
A24: =CONCATENATE(B24,C24) -> LightningCash Cash feat. John Rzeznik | B24: Lightning | C24: Cash Cash feat. John Rzeznik | D24: 2014 | E24: 2010s | F24: Dance / Disco, Pop | H24: Male | J24: High | L24: normalized featured artist formatting | M24: KCDPR1408-06 - Cash Cash & John Rzeznik - Lightning.cdg
A25: =CONCATENATE(B25,C25) -> I Don’t Know Why I Love You But I DoCharley Pride | B25: I Don’t Know Why I Love You But I Do | C25: Charley Pride | D25: 1972 | E25: 70s | F25: Country | H25: Male | I25: Possible Duplicate | J25: High | L25: variant version present | M25: DFK091-08 - Charley Pride - I Don't Know Why I Love You But I Do (Wbgv).zip
A26: =CONCATENATE(B26,C26) -> I Don’t Know Why I Love You But I Do (with vocal)Charley Pride | B26: I Don’t Know Why I Love You But I Do (with vocal) | C26: Charley Pride | D26: 1972 | E26: 70s | F26: Country | H26: Male | J26: High | M26: DFK091-07 - Charley Pride - I Don't Know Why I Love You But I Do (Wvocal).zip
A27: =CONCATENATE(B27,C27) -> Boom ClapCharli XCX | B27: Boom Clap | C27: Charli XCX | D27: 2014 | E27: 2010s | F27: Pop | G27: Group Songs | H27: Female | J27: High | L27: normalized artist spelling | M27: G28870 - Boom Clap - Charlie XCX.cdg
A28: =CONCATENATE(B28,C28) -> Ready Set RollChase Rice | B28: Ready Set Roll | C28: Chase Rice | D28: 2014 | E28: 2010s | F28: Country | H28: Male | J28: High | L28: reversed order fixed | M28: A28546 - Ready Set Roll - Chase Rice.cdg
A29: =CONCATENATE(B29,C29) -> StampedeChris LeDoux | B29: Stampede | C29: Chris LeDoux | D29: 1993 | E29: 90s | F29: Country | H29: Male | J29: High | M29: Chris_LeDoux_Stampede(MP3+CDG_Karaoke)_10405499.zip
A30: =CONCATENATE(B30,C30) -> AnacondaNicki Minaj | B30: Anaconda | C30: Nicki Minaj | D30: 2014 | E30: 2010s | F30: Hip-Hop, Rap | H30: Female | J30: High | L30: removed catalog code and file extension
A31: =CONCATENATE(B31,C31) -> Travelin’ SoldierCody Johnson | B31: Travelin’ Soldier | C31: Cody Johnson | D31: 2019 | E31: 2010s | F31: Country | H31: Male | J31: Medium | K31: Yes | L31: cover vs original (Dixie Chicks) | M31: Cody_Johnson_Travelin_Soldier(MP3+CDG_Karaoke)_10989200.zip
A32: =CONCATENATE(B32,C32) -> Drivin’ Around SongColt Ford ft. Jason Aldean | B32: Drivin’ Around Song | C32: Colt Ford ft. Jason Aldean | D32: 2013 | E32: 2010s | F32: Country | H32: Male | J32: High | L32: kept feature | M32: ASK1209C-02 - Colt Ford & Jason Aldean - Drivin' Around Song.zip
A33: =CONCATENATE(B33,C33) -> Bad BloodBastille | B33: Bad Blood | C33: Bastille | D33: 2013 | E33: 2010s | F33: Alternative / Indie, Pop | G33: Group Songs | H33: Male | J33: High | L33: removed catalog code and file extension
A34: =CONCATENATE(B34,C34) -> Outta My HeadCraig Campbell | B34: Outta My Head | C34: Craig Campbell | D34: 2012 | E34: 2010s | F34: Country | H34: Male | J34: High | M34: ASK1209C-04 - Craig Campbell - Outta My Head.zip
A35: =CONCATENATE(B35,C35) -> Young in AmericaDanielle Bradbery | B35: Young in America | C35: Danielle Bradbery | D35: 2014 | E35: 2010s | F35: Country | H35: Female | J35: High | L35: normalized title capitalization | M35: KCD1408-03 - Danielle Bradbery - Young In America.cdg
A36: =CONCATENATE(B36,C36) -> True BelieversDarius Rucker | B36: True Believers | C36: Darius Rucker | D36: 2013 | E36: 2010s | F36: Country | H36: Male | J36: High | M36: ASK1209C-09 - Darius Rucker - True Believers.zip
A37: =CONCATENATE(B37,C37) -> Shot Me DownDavid Guetta feat. Skylar Grey | B37: Shot Me Down | C37: David Guetta feat. Skylar Grey | D37: 2014 | E37: 2010s | F37: Dance / Disco, Pop | H37: Male | J37: High | L37: normalized featured artist formatting | M37: KCD1407-2-03 - David Guetta & Skylar Grey - Shot Me Down.cdg
A38: =CONCATENATE(B38,C38) -> Neon LightsDemi Lovato | B38: Neon Lights | C38: Demi Lovato | D38: 2013 | E38: 2010s | F38: Pop, Dance / Disco | H38: Female | J38: High | L38: removed catalog code and file extension | M38: SF341-17 - Demi Lovato - Neon Lights.cdg
A39: =CONCATENATE(B39,C39) -> Really Don't CareDemi Lovato feat. Cher Lloyd | B39: Really Don't Care | C39: Demi Lovato feat. Cher Lloyd | D39: 2014 | E39: 2010s | F39: Pop | G39: Group Songs | H39: Female | J39: High | L39: normalized featured artist formatting | M39: KCDPR1408-10 - Demi Lovato & Cher Lloyd - Really Don't Care.cdg
A40: =CONCATENATE(B40,C40) -> Country & Cold CansDierks Bentley | B40: Country & Cold Cans | C40: Dierks Bentley | D40: 2012 | E40: 2010s | F40: Country | H40: Male | J40: High | M40: ASK1209C-01 - Dierks Bentley - Country & Cold Cans.zip
...

Sheet 2-4
A1: Name
A2: Alicia_Keys_Girl_On_Fire_(Main_Version)_160717.mp4
A3: Bad Romance.3gp
A4: LMFAO - Party Rock Anthem
A5: Adele - Rolling In The Deep
A6: SF296-09 - Adele - Make You Feel My Love
A7: SF302-18 - Adele - Promise This
A8: SF303-18 Adele - Set Fire To The Rain
A9: SF307-01 - Adele - One And Only
A10: SFPL023-08 - Adele - Chasing Pavements
A11: SFPL023-09 - Adele - Cold Shoulder
A12: Zoom Karaoke - Someone Like You - Adele
... A1377: Zac Brown Band - Homegrown

Sheet songs
A1: FullName | B1: Name
A2: D:\Karaoke\new\01-30-26\Blink_182_Mutt(MP3+CDG_Karaoke)_10964551.zip | B2: Blink_182_Mutt(MP3+CDG_Karaoke)_10964551.zip
A3: D:\Karaoke\new\01-30-26\Bowling_for_Soup_High_School_Never_Ends(MP3+CDG_Karaoke)_10558576.zip | B3: Bowling_for_Soup_High_School_Never_Ends(MP3+CDG_Karaoke)_10558576.zip
A4: D:\Karaoke\new\01-30-26\Chris_LeDoux_Stampede(MP3+CDG_Karaoke)_10405499.zip | B4: Chris_LeDoux_Stampede(MP3+CDG_Karaoke)_10405499.zip
A5: D:\Karaoke\new\01-30-26\Cody_Johnson_Travelin_Soldier(MP3+CDG_Karaoke)_10989200.zip | B5: Cody_Johnson_Travelin_Soldier(MP3+CDG_Karaoke)_10989200.zip
A6: D:\Karaoke\new\01-30-26\Harry_Styles_Adore_You(MP3+CDG_Karaoke)_10366793.zip | B6: Harry_Styles_Adore_You(MP3+CDG_Karaoke)_10366793.zip
A7: D:\Karaoke\new\01-30-26\Harry_Styles_As_It_Was(MP3+CDG_Karaoke)_10602886.zip | B7: Harry_Styles_As_It_Was(MP3+CDG_Karaoke)_10602886.zip
A8: D:\Karaoke\new\01-30-26\Harry_Styles_Keep_Driving(MP3+CDG_Karaoke)_10631199.zip | B8: Harry_Styles_Keep_Driving(MP3+CDG_Karaoke)_10631199.zip
A9: D:\Karaoke\new\01-30-26\Harry_Styles_Matilda(MP3+CDG_Karaoke)_10619342.zip | B9: Harry_Styles_Matilda(MP3+CDG_Karaoke)_10619342.zip
A10: D:\Karaoke\new\01-30-26\Harry_Styles_Sign_of_the_Times(MP3+CDG_Karaoke)_10184008.zip | B10: Harry_Styles_Sign_of_the_Times(MP3+CDG_Karaoke)_10184008.zip
A11: D:\Karaoke\new\01-30-26\Harry_Styles_Sweet_Creature(MP3+CDG_Karaoke)_10428735.zip | B11: Harry_Styles_Sweet_Creature(MP3+CDG_Karaoke)_10428735.zip
A12: D:\Karaoke\new\01-30-26\Hot_Mulligan_Equip_Sunglasses(MP3+CDG_Karaoke)_10920728.zip | B12: Hot_Mulligan_Equip_Sunglasses(MP3+CDG_Karaoke)_10920728.zip
... A2387: D:\Karaoke\new\Kkaraoke 2-23-25\Zach_Bryan_Sun_to_Me(MP3+CDG_Karaoke)_10727727.zip | B2387: Zach_Bryan_Sun_to_Me(MP3+CDG_Karaoke)_10727727.zip

Sheet songs2
A1: FullName | B1: Name
A2: D:\Karaoke\butches laptop\Karaoke\Alicia_Keys_Girl_On_Fire_(Main_Version)_160717.mp4 | B2: Alicia_Keys_Girl_On_Fire_(Main_Version)_160717.mp4
A3: D:\Karaoke\butches laptop\Karaoke\Bad Romance.3gp | B3: Bad Romance.3gp
A4: D:\Karaoke\butches laptop\Karaoke\ - LMFAO - Party Rock Anthem\- LMFAO - Party Rock Anthem.cdg | B4: =- LMFAO - Party Rock Anthem.cdg -> #NAME?
A5: D:\Karaoke\butches laptop\Karaoke\ - LMFAO - Party Rock Anthem\- LMFAO - Party Rock Anthem.mp3 | B5: =- LMFAO - Party Rock Anthem.mp3 -> #NAME?
A6: D:\Karaoke\butches laptop\Karaoke\Adele\Adele - Rolling In The Deep [Karaoke].cdg | B6: Adele - Rolling In The Deep [Karaoke].cdg
A7: D:\Karaoke\butches laptop\Karaoke\Adele\Adele - Rolling In The Deep [Karaoke].mp3 | B7: Adele - Rolling In The Deep [Karaoke].mp3
A8: D:\Karaoke\butches laptop\Karaoke\Adele\SF296-09 - Adele - Make You Feel My Love.cdg | B8: SF296-09 - Adele - Make You Feel My Love.cdg
A9: D:\Karaoke\butches laptop\Karaoke\Adele\SF296-09 - Adele - Make You Feel My Love.mp3 | B9: SF296-09 - Adele - Make You Feel My Love.mp3
A10: D:\Karaoke\butches laptop\Karaoke\Adele\SF302-18 - Adele - Promise This.cdg | B10: SF302-18 - Adele - Promise This.cdg
A11: D:\Karaoke\butches laptop\Karaoke\Adele\SF302-18 - Adele - Promise This.mp3 | B11: SF302-18 - Adele - Promise This.mp3
A12: D:\Karaoke\butches laptop\Karaoke\Adele\SF303-18 Adele - Set Fire To The Rain.cdg | B12: SF303-18 Adele - Set Fire To The Rain.cdg
A13: D:\Karaoke\butches laptop\Karaoke\Adele\SF303-18 Adele - Set Fire To The Rain.mp3 | B13: SF303-18 Adele - Set Fire To The Rain.mp3
A14: D:\Karaoke\butches laptop\Karaoke\Adele\SF307-01 - Adele - One And Only.cdg | B14: SF307-01 - Adele - One And Only.cdg
A15: D:\Karaoke\butches laptop\Karaoke\Adele\SF307-01 - Adele - One And Only.mp3 | B15: SF307-01 - Adele - One And Only.mp3
A16: D:\Karaoke\butches laptop\Karaoke\Adele\SFPL023-08 - Adele - Chasing Pavements.cdg | B16: SFPL023-08 - Adele - Chasing Pavements.cdg
A17: D:\Karaoke\butches laptop\Karaoke\Adele\SFPL023-08 - Adele - Chasing Pavements.mp3 | B17: SFPL023-08 - Adele - Chasing Pavements.mp3
... A1475: D:\Karaoke\butches laptop\Karaoke\Zac Brown Band - Keep Me In Mind\Zac Brown Band - Keep Me In Mind.mp3 | B1475: Zac Brown Band - Keep Me In Mind.mp3

Sheet songs4
A1: Name
A2: Blake Shelton - Hillbilly Bone.cdg
A3: Blake Shelton - Hillbilly Bone.mp3
A4: AC-DC - Back In Black.cdg
A5: AC-DC - Back In Black.mp3
A6: AC-DC - Big Balls.cdg
A7: AC-DC - Big Balls.mp3
A8: AC-DC - For Those About To Rock.cdg
A9: AC-DC - For Those About To Rock.mp3
A10: AC-DC - Girls Got Rythm.cdg
A11: AC-DC - Girls Got Rythm.MP3
A12: AC-DC - Hells Bells.cdg
... A1127: SC3437-07 - Miranda Lambert - Bring Me Down.mp3

Sheet songs3
A1: Name
A2: - Eli Young Band - Drunk Last Night.zip
A3: A Thousand Horses - Smoke.zip
A4: Aldean, Jason - Dont You Wanna Stay (duet Kelly Clarkson).zip
A5: Aldean, Jason - Just Gettin Started.zip
A6: Aldean, Jason - Take A Little Ride.zip
A7: Allan, Gary - Every Storm (Runs Out Of Rain).zip
A8: Amazon-MP3-1428732197.amz
A9: Bates, Greg - Did It For The Girl.zip
A10: Bentley, Dierks - Say You Do.zip
A11: BKD - Little Big Town - Girl Crush.zip
A12: BKD - Musgraves, Kacey - Blowin Smoke.zip
... A44: Little Big Town - Day Drinking.zip
A45: Little Big Town - Your Side Of the Bed.zip | K45: 1475
A46: Love And Theft - Angel Eyes.zip | K46: 79
A47: Love And Theft - Whiskey On My Breath (1).zip | K47: 1127
A48: Love And Theft - Whiskey On My Breath.zip | K48: =SUM(K45:K47) -> 2681
A49: Lynch, Dustin - Cowboys And Angels.zip
A50: Magic! - Rude.zip
A51: Maroon 5 - Sugar (1).zip
A52: Maroon 5 - Sugar.zip
A53: Mars, Bruno - Uptown Funk (w. Mark Ronson).zip
A54: McEntire, Reba - Going Out Like That.zip
A55: Miguel - Adorn.zip
A56: Moore, Kip - Beer Money.zip
A57: Moore, Kip - Something Bout A Truck.zip
A58: Mumford and Sons - Little Lion Man.zip
A59: Musiq - Halfcrazy.zip
A60: Old Crow Medicine Show - Wagon Wheel.zip
... A79: Zac Brown Band - Homegrown.zip
